#### 사이버보안학과 201520930 김희승
# 에러 처리

RxJava는 에러가 발생했을 떄 처리 방법으로 세가지를 제공한다.

* 소비자(`Subscriber` / `Observer`)에게 에러 통지
* 처리 작업 재시도(retry)
* 대체 데이터 통지

하지만, 에러 통지를 받아도 되돌아 갈 수 없는 `VirtualMachineError`같은 종류의 에러는 별도 처리 없이 바로 던지기도 한다. </br>
또한, 통지 처리 작업 중에 발생한 에러를 소비자에게 에러로 통지할지, 그대로 자바 예외나 에러로 던질지는 `Exception` 클래스의 `throwIfFatal` 메서드에 정의되어있다.

## 소비자에게 에러 통지하기

`subscribe`메서드에서 에러 통지 처리를 할 수 있다. </br>
에러 통지 처리가 설정되지 않은 `subscribe`로 구독할 때는 에러가 발생해도 `stackTrace`만 출력된다. 그래서 에러가 발생했다는 것을 인식하지 못할 수 있다.

## 처리 재시도

에러가 발생하더라도 네트워크 중단과 같이 재시도하면 정상적인 처리를 할 수 있을 때도 있다. 재시도를 하게 될 떄는 소비자에게 에러를 통지하지 않는다.

이러한 작업을 위해 RxJava는 `retry`라는 에러 발생시 재실행 메서드를 제공한다. 이 메서드는 통지 처리를 처음부터 다시 시작한다.

```kotlin
fun main() {
    val flowable = Flowable.create({ emitter: FlowableEmitter<Int> ->
        println("처리 시작")

        for (i in 1..3) {
            if (i == 2) {
                throw Exception("예외 발생")
            }

            emitter.onNext(i)
        }

        emitter.onComplete()
        println("처리 완료")
    }, BackpressureStrategy.BUFFER)
        .doOnSubscribe { subscription ->
            println("flowable: doOnSubscribe")
        }
        .retry(2)

    flowable.subscribe(object : Subscriber<Int> {
        override fun onSubscribe(s: Subscription?) {
            println("subscriber: OnSubscribe")
            s?.request(Long.MAX_VALUE)
        }

        override fun onNext(t: Int?) {
            println("data: $t")
        }

        override fun onError(t: Throwable?) {
            println("error: $t")
        }

        override fun onComplete() {
            println("종료")
        }

    })
}
```

```text
subscriber: OnSubscribe
flowable: doOnSubscribe
처리 시작
data: 1
flowable: doOnSubscribe
처리 시작
data: 1
flowable: doOnSubscribe
처리 시작
data: 1
error: java.lang.Exception: 예외 발생
```

## 대체 데이터 통지

에러가 발생하면 대체 데이터를 통지해 처리 작업을 에러로 끝내지 않고 완료하게 하는 에러 처리 방법이다. </br>
`onError`나 `onException`으로 시작하는 메서드를 활용하면 된다.

```kotlin
fun main() {
    Flowable.just(1, 3, 5, 0, 2, 4)
        .map { data ->
            100 / data
        }
        .onErrorReturnItem(0)
        .subscribe(object : DisposableSubscriber<Int>() {
            override fun onNext(t: Int?) {
                println("data: $t")
            }

            override fun onError(t: Throwable?) {
                println("error: $t")
            }

            override fun onComplete() {
                println("완료")
            }
        })
}
```

```text
data: 100
data: 33
data: 20
data: 0
완료
```

위 예시에서는 원본 데이터가 0일때 `map` 메서드에서 에러가 발생하지만, `onErrorReturnItem`을 통해서 0을 통지하게 된다. 이 때, 추가(남은 데이터) 통지와 에러 통지 없이 완료를 통지해서
정상적으로 종료된다. 
